<?xml version="1.0" ?>
<!-- =================================================================================== -->
<!-- |    This document was autogenerated by xacro from pole_2_links.xacro             | -->
<!-- |    EDITING THIS FILE BY HAND IS NOT RECOMMENDED                                 | -->
<!-- =================================================================================== -->
<robot name="pole">
  <material name="dark_gray">
    <color rgba="0.2 0.2 0.2 1.0"/>
  </material>
  <material name="gray">
    <color rgba="0.3 0.3 0.3 1.0"/>
  </material>
  <material name="light_gray">
    <color rgba="0.4 0.4 0.4 1.0"/>
  </material>
  <material name="yellow">
    <color rgba="0.8 0.8 0.0 1.0"/>
  </material>
  <material name="teal">
    <color rgba="0.0 1.0 1.0 1.0"/>
  </material>
  <material name="black">
    <color rgba="0.15 0.15 0.15 1.0"/>
  </material>
  <!-- Base link -->
  <link name="base_link"/>
  <!-- Definition of links -->
  <link name="cartesian_parent_link"/>
  <link name="cartesian_x_link"/>
  <link name="cartesian_y_link"/>
  <link name="cartesian_z_link"/>
  <!-- Prismatic joint along X-axis -->
  <joint name="cartesian_x_joint" type="prismatic">
    <origin rpy="0 0 0" xyz="0 0 0"/>
    <parent link="cartesian_parent_link"/>
    <child link="cartesian_x_link"/>
    <axis xyz="1 0 0"/>
    <limit effort="1" lower="-3" upper="3" velocity="1.5"/>
  </joint>
  <!-- Prismatic joint along Y-axis -->
  <joint name="cartesian_y_joint" type="prismatic">
    <origin rpy="0 0 0" xyz="0 0 0"/>
    <parent link="cartesian_x_link"/>
    <child link="cartesian_y_link"/>
    <axis xyz="0 1 0"/>
    <limit effort="1" lower="-3" upper="3" velocity="1.5"/>
  </joint>
  <!-- Prismatic joint along Z-axis -->
  <joint name="cartesian_z_joint" type="prismatic">
    <origin rpy="0 0 0" xyz="0 0 0"/>
    <parent link="cartesian_y_link"/>
    <child link="cartesian_z_link"/>
    <axis xyz="0 0 1"/>
    <limit effort="1" lower="0.0" upper="3" velocity="1.5"/>
  </joint>
  <!-- Definition of links -->
  <link name="spherical_parent_link"/>
  <link name="spherical_roll_link"/>
  <link name="spherical_pitch_link"/>
  <link name="spherical_yaw_link"/>
  <!-- Revolute joint around Z-axis -->
  <joint name="spherical_yaw_joint" type="revolute">
    <origin rpy="0 0 0" xyz="0 0 0"/>
    <parent link="spherical_parent_link"/>
    <child link="spherical_yaw_link"/>
    <axis xyz="0 0 1"/>
    <limit effort="1" lower="-3.141592653589793" upper="3.141592653589793" velocity="1.5707963267948966"/>
  </joint>
  <!-- Revolute joint around Y-axis -->
  <joint name="spherical_pitch_joint" type="revolute">
    <origin rpy="0 0 0" xyz="0 0 0"/>
    <parent link="spherical_yaw_link"/>
    <child link="spherical_pitch_link"/>
    <axis xyz="0 1 0"/>
    <limit effort="1" lower="-3.141592653589793" upper="3.141592653589793" velocity="1.5707963267948966"/>
  </joint>
  <!-- Revolute joint around X-axis -->
  <joint name="spherical_roll_joint" type="revolute">
    <origin rpy="0 0 0" xyz="0 0 0"/>
    <parent link="spherical_pitch_link"/>
    <child link="spherical_roll_link"/>
    <axis xyz="1 0 0"/>
    <limit effort="1" lower="-3.141592653589793" upper="3.141592653589793" velocity="1.5707963267948966"/>
  </joint>
  <!-- Tool link is where the tip of the combined cartesian + spherical joints is at -->
  <link name="tool00"/>
  <!-- Connections between components -->
  <!-- Connect Cartesian joint system to the base -->
  <joint name="base_to_cartesian" type="fixed">
    <origin rpy="0 0 0" xyz="0 0 0"/>
    <parent link="base_link"/>
    <child link="cartesian_parent_link"/>
  </joint>
  <!-- Connect spherical joint to the top of the cartesian joint -->
  <joint name="cartesian_to_spherical" type="fixed">
    <origin rpy="0 0 0" xyz="0 0 0"/>
    <parent link="cartesian_z_link"/>
    <child link="spherical_parent_link"/>
  </joint>
  <!-- Connect the tool link with the the tip of the combined cartesian + spherical joints -->
  <joint name="spherical_to_tool00" type="fixed">
    <origin rpy="0 0 0" xyz="0 0 0"/>
    <parent link="spherical_roll_link"/>
    <child link="tool00"/>
  </joint>
  <!-- +++++++++++++++++++++++++++++++++++++++++++++++++++++++++++++++++++ -->
  <!-- Add a link from tool00 to left -->
  <link name="link_left_1_root">
    <visual>
      <geometry>
        <cylinder length="1.6764" radius="0.035"/>
      </geometry>
      <origin rpy="0 0 0" xyz="0 0 0.8382"/>
      <material name="teal"/>
    </visual>
    <collision>
      <geometry>
        <cylinder length="1.6764" radius="0.035"/>
      </geometry>
      <origin rpy="0 0 0" xyz="0 0 0.8382"/>
    </collision>
  </link>
  <!-- Connect tool00 to the root of left link -->
  <joint name="tool00_to_link_left_1_root" type="fixed">
    <origin rpy="0 0 0" xyz="0 0 0"/>
    <parent link="tool00"/>
    <child link="link_left_1_root"/>
  </joint>
  <!-- Define the tip of the left link -->
  <link name="link_left_1_tip"/>
  <!-- Connect the tip to the root with a fixed joint -->
  <joint name="joint_link_left_1_root_to_tip" type="fixed">
    <origin rpy="0 0 0" xyz="0 0 1.6764"/>
    <parent link="link_left_1_root"/>
    <child link="link_left_1_tip"/>
  </joint>
  <!-- Define another link to come back to the root -->
  <link name="link_left_1_root_back"/>
  <!-- Connect the tip to the root with a fixed joint -->
  <joint name="joint_link_left_1_tip_to_root_back" type="fixed">
    <origin rpy="0 0 0" xyz="0 0 -1.6764"/>
    <parent link="link_left_1_tip"/>
    <child link="link_left_1_root_back"/>
  </joint>
  <!-- Define the spherical joint -->
  <link name="link_yaw"/>
  <!-- Revolute joint around Z-axis -->
  <joint name="joint_yaw" type="revolute">
    <origin rpy="0 0 0" xyz="0 0 0"/>
    <parent link="link_left_1_root_back"/>
    <child link="link_yaw"/>
    <axis xyz="0 0 1"/>
    <limit effort="1" lower="-1.5707963267948966" upper="1.5707963267948966" velocity="1.5707963267948966"/>
  </joint>
  <link name="link_pitch"/>
  <!-- Revolute joint around Y-axis -->
  <joint name="joint_pitch" type="revolute">
    <origin rpy="0 0 0" xyz="0 0 0"/>
    <parent link="link_yaw"/>
    <child link="link_pitch"/>
    <axis xyz="0 1 0"/>
    <limit effort="1" lower="-1.5707963267948966" upper="1.5707963267948966" velocity="1.5707963267948966"/>
  </joint>
  <!-- Add a link from the root back to right -->
  <link name="link_right_1_root">
    <visual>
      <geometry>
        <cylinder length="1.6764" radius="0.035"/>
      </geometry>
      <origin rpy="0 0 0" xyz="0 0 -0.8382"/>
      <material name="teal"/>
    </visual>
    <collision>
      <geometry>
        <cylinder length="1.6764" radius="0.035"/>
      </geometry>
      <origin rpy="0 0 0" xyz="0 0 -0.8382"/>
    </collision>
  </link>
  <!-- Connect the root back to the right link with a revolute joint from the x axis-->
  <joint name="joint_link_left_1_root_back_to_right_1_root" type="revolute">
    <origin rpy="0 0 0" xyz="0 0 0"/>
    <parent link="link_pitch"/>
    <child link="link_right_1_root"/>
    <axis xyz="1 0 0"/>
    <limit effort="1" lower="-1.5707963267948966" upper="1.5707963267948966" velocity="1.5707963267948966"/>
  </joint>
  <!-- Define the tip of the right link -->
  <link name="link_right_1_tip"/>
  <!-- Connect the tip to the root with a fixed joint -->
  <joint name="joint_link_right_1_root_to_tip" type="fixed">
    <origin rpy="0 0 0" xyz="0 0 -1.6764"/>
    <parent link="link_right_1_root"/>
    <child link="link_right_1_tip"/>
  </joint>
  <!-- Define another link to come back to the root -->
  <link name="link_right_1_root_back"/>
  <!-- Connect the tip to the root with a fixed joint -->
  <joint name="joint_link_right_1_tip_to_root_back" type="fixed">
    <origin rpy="0 0 0" xyz="0 0 1.6764"/>
    <parent link="link_right_1_tip"/>
    <child link="link_right_1_root_back"/>
  </joint>
  <!-- Define final tool as tool0 link -->
  <link name="tool0"/>
  <!-- Connect the right root back to the tool0 link -->
  <joint name="joint_link_right_1_root_back_to_tool0" type="fixed">
    <origin rpy="0 0 0" xyz="0 0 0"/>
    <parent link="link_right_1_root_back"/>
    <child link="tool0"/>
  </joint>

  <!-- Create robot holding points as fixed links -->
  <link name="pole_holder_link_5"/>
  
  <joint name="pole_holder_fixed_joint_5" type="fixed">
    <parent link="link_right_1_root_back"/>
    <child link="pole_holder_link_5"/>
    <origin rpy="0 0 0" xyz="0 0 -1.2153899999999997"/>
  </joint>


  <link name="pole_holder_link_34"/>
  
  <joint name="pole_holder_fixed_joint_34" type="fixed">
    <parent link="link_left_1_root_back"/>
    <child link="pole_holder_link_34"/>
    <origin rpy="0 0 0" xyz="0 0 1.21539"/>
  </joint>
</robot>

