<?xml version="1.0" ?>
<!-- =================================================================================== -->
<!-- |    This document was autogenerated by xacro from pole_1_links.xacro             | -->
<!-- |    EDITING THIS FILE BY HAND IS NOT RECOMMENDED                                 | -->
<!-- =================================================================================== -->
<robot name="pole">
  <material name="dark_gray">
    <color rgba="0.2 0.2 0.2 1.0"/>
  </material>
  <material name="gray">
    <color rgba="0.3 0.3 0.3 1.0"/>
  </material>
  <material name="light_gray">
    <color rgba="0.4 0.4 0.4 1.0"/>
  </material>
  <material name="yellow">
    <color rgba="0.8 0.8 0.0 1.0"/>
  </material>
  <material name="teal">
    <color rgba="0.0 1.0 1.0 1.0"/>
  </material>
  <material name="black">
    <color rgba="0.15 0.15 0.15 1.0"/>
  </material>
  <!-- Base link -->
  <link name="base_link"/>
  <!-- Definition of links -->
  <link name="cartesian_parent_link"/>
  <link name="cartesian_x_link"/>
  <link name="cartesian_y_link"/>
  <link name="cartesian_z_link"/>
  <!-- Prismatic joint along X-axis -->
  <joint name="cartesian_x_joint" type="prismatic">
    <origin rpy="0 0 0" xyz="0 0 0"/>
    <parent link="cartesian_parent_link"/>
    <child link="cartesian_x_link"/>
    <axis xyz="1 0 0"/>
    <limit effort="10000" lower="-0.5" upper="0.5" velocity="1.5"/>
  </joint>
  <!-- Prismatic joint along Y-axis -->
  <joint name="cartesian_y_joint" type="prismatic">
    <origin rpy="0 0 0" xyz="0 0 0"/>
    <parent link="cartesian_x_link"/>
    <child link="cartesian_y_link"/>
    <axis xyz="0 1 0"/>
    <limit effort="10000" lower="-0.5" upper="0.5" velocity="1.5"/>
  </joint>
  <!-- Prismatic joint along Z-axis -->
  <joint name="cartesian_z_joint" type="prismatic">
    <origin rpy="0 0 0" xyz="0 0 0"/>
    <parent link="cartesian_y_link"/>
    <child link="cartesian_z_link"/>
    <axis xyz="0 0 1"/>
    <limit effort="10000" lower="-0.5" upper="0.5" velocity="1.5"/>
  </joint>
  <!-- Definition of links -->
  <link name="spherical_parent_link"/>
  <link name="spherical_roll_link"/>
  <link name="spherical_pitch_link"/>
  <link name="spherical_yaw_link"/>
  <!-- Revolute joint around Z-axis -->
  <joint name="spherical_yaw_joint" type="revolute">
    <origin rpy="0 0 0" xyz="0 0 0"/>
    <parent link="spherical_parent_link"/>
    <child link="spherical_yaw_link"/>
    <axis xyz="0 0 1"/>
    <limit effort="1" lower="-3.141592653589793" upper="3.141592653589793" velocity="1.5707963267948966"/>
  </joint>
  <!-- Revolute joint around Y-axis -->
  <joint name="spherical_pitch_joint" type="revolute">
    <origin rpy="0 0 0" xyz="0 0 0"/>
    <parent link="spherical_yaw_link"/>
    <child link="spherical_pitch_link"/>
    <axis xyz="0 1 0"/>
    <limit effort="1" lower="-3.141592653589793" upper="3.141592653589793" velocity="1.5707963267948966"/>
  </joint>
  <!-- Revolute joint around X-axis -->
  <joint name="spherical_roll_joint" type="revolute">
    <origin rpy="0 0 0" xyz="0 0 0"/>
    <parent link="spherical_pitch_link"/>
    <child link="spherical_roll_link"/>
    <axis xyz="1 0 0"/>
    <limit effort="1" lower="-3.141592653589793" upper="3.141592653589793" velocity="1.5707963267948966"/>
  </joint>
  <!-- Tool link is where the tip of the combined cartesian + spherical joints is at -->
  <link name="tool0"/>
  <!-- Connections between components -->
  <!-- Connect Cartesian joint system to the base -->
  <joint name="base_to_cartesian" type="fixed">
    <origin rpy="0 0 0" xyz="0 0 0"/>
    <parent link="base_link"/>
    <child link="cartesian_parent_link"/>
  </joint>
  <!-- Connect spherical joint to the top of the cartesian joint -->
  <joint name="cartesian_to_spherical" type="fixed">
    <origin rpy="0 0 0" xyz="0 0 0"/>
    <parent link="cartesian_z_link"/>
    <child link="spherical_parent_link"/>
  </joint>
  <!-- Connect the tool link with the the tip of the combined cartesian + spherical joints -->
  <joint name="spherical_to_tool0" type="fixed">
    <origin rpy="0 0 0" xyz="0 0 0"/>
    <parent link="spherical_roll_link"/>
    <child link="tool0"/>
  </joint>
  <!-- Visual and collision for center link -->
  <link name="cylindrical_center_link">
    <visual>
      <geometry>
        <cylinder length="0.5" radius="0.0035"/>
      </geometry>
      <origin rpy="0 0 0" xyz="0 0 0"/>
      <material name="teal"/>
    </visual>
    <collision>
      <geometry>
        <cylinder length="0.5" radius="0.0035"/>
      </geometry>
      <origin rpy="0 0 0" xyz="0 0 0"/>
    </collision>
  </link>
  <link name="cylindrical_end1_link"/>
  <link name="cylindrical_end2_link"/>
  <joint name="cylindrical_end1_joint" type="fixed">
    <origin rpy="0 0 0" xyz="0 0 0.25"/>
    <parent link="cylindrical_center_link"/>
    <child link="cylindrical_end1_link"/>
  </joint>
  <joint name="cylindrical_end2_joint" type="fixed">
    <origin rpy="0 0 0" xyz="0 0 -0.25"/>
    <parent link="cylindrical_center_link"/>
    <child link="cylindrical_end2_link"/>
  </joint>
  <!-- Connect Cylindrical Link to the top of the tool -->
  <joint name="tool0_to_cylindrical" type="fixed">
    <origin rpy="0 0 0" xyz="0 0 0"/>
    <parent link="tool0"/>
    <child link="cylindrical_center_link"/>
  </joint>
  <!-- Create robot holding points as fixed links -->
  <link name="pole_holder_link_0"/>
  <joint name="pole_holder_fixed_joint_0" type="fixed">
    <parent link="tool0"/>
    <child link="pole_holder_link_0"/>
    <origin rpy="0 0 0" xyz="0 0 -0.24375"/>
  </joint>
  <link name="pole_holder_link_39"/>
  <joint name="pole_holder_fixed_joint_39" type="fixed">
    <parent link="tool0"/>
    <child link="pole_holder_link_39"/>
    <origin rpy="0 0 0" xyz="0 0 0.24375000000000002"/>
  </joint>
</robot>

